<!-- <?xml version="1.0" encoding="utf-8"?> -->
<!-- This URDF was automatically created by SolidWorks to URDF Exporter! Originally created by Stephen Brawner (brawner@gmail.com) 
     Commit Version: 1.6.0-4-g7f85cfe  Build Version: 1.6.7995.38578
     For more information, please see http://wiki.ros.org/sw_urdf_exporter -->
<robot
  name="ver4">
  <link
    name="base_link">
    <inertial>
      <origin
        xyz="-0.0222751569698722 0.0118585384555541 0.116332514439535"
        rpy="0 0 0" />
      <mass
        value="12.8783005904919" />
      <inertia
        ixx="0.110515825421358"
        ixy="-0.000215611801606853"
        ixz="0.000971112344179321"
        iyy="0.128895088615439"
        iyz="0.000357426284463578"
        izz="0.233156162778662" />
    </inertial>
    <visual>
      <origin
        xyz="0 0 0"
        rpy="0 0 0" />
      <geometry>
        <mesh
          filename="package://car_3_wheel/meshes/base_link.STL" />
      </geometry>
      <material
        name="">
        <color
          rgba="0.898039215686275 0.898039215686275 0.898039215686275 1" />
      </material>
    </visual>
    <collision>
      <origin
        xyz="0 0 0"
        rpy="0 0 0" />
      <geometry>
        <mesh
          filename="package://car_3_wheel/meshes/base_link.STL" />
      </geometry>
    </collision>
  </link>

  <gazebo reference="base_link">
    <mu1>200</mu1>
    <mu2>200</mu2>
    <kp>1000000</kp>
    <kd>1</kd>
    <material>Gazebo/Red</material>
  </gazebo>


  <link
    name="car_left">
    <inertial>
      <origin
        xyz="0.0002288419618732 -0.000132204138624934 -0.0180084261510948"
        rpy="0 0 0" />
      <mass
        value="0.579007065567467" />
      <inertia
        ixx="0.00139158331696"
        ixy="2.72612647396894E-06"
        ixz="8.85387209201048E-07"
        iyy="0.00139093173055907"
        iyz="-2.59323913956156E-07"
        izz="0.00263447481829552" />
    </inertial>
    <visual>
      <origin
        xyz="0 0 0"
        rpy="0 0 0" />
      <geometry>
        <mesh
          filename="package://car_3_wheel/meshes/car_left.STL" />
      </geometry>
      <material
        name="">
        <color
          rgba="1 0.549019607843137 0 1" />
      </material>
    </visual>
    <collision>
      <origin
        xyz="0 0 0"
        rpy="0 0 0" />
      <geometry>
        <mesh
          filename="package://car_3_wheel/meshes/car_left.STL" />
      </geometry>
    </collision>
  </link>
  <joint
    name="car_left_joint"
    type="continuous">
    <origin
      xyz="-0.095546 0.24067 0.084802"
      rpy="-1.5708 0 0" />
    <parent
      link="base_link" />
    <child
      link="car_left" />
    <axis
      xyz="0 0 1" />
    <limit
      effort="10"
      velocity="10" />
    <dynamics
      damping="0.1"
      friction="0.1" />
  </joint>

  <gazebo reference="car_left">
    <mu1>200</mu1>
    <mu2>200</mu2>
    <kp>1000000</kp>
    <kd>1</kd>
    <material>Gazebo/Black</material>
  </gazebo>

  <link
    name="car_right">
    <inertial>
      <origin
        xyz="-0.000260216250702383 -4.61723206129448E-05 0.0180084270297736"
        rpy="0 0 0" />
      <mass
        value="0.579007235319938" />
      <inertia
        ixx="0.00138975795650939"
        ixy="-2.29982712912359E-06"
        ixz="9.20726523880039E-07"
        iyy="0.00139275709100968"
        iyz="-5.8498468257902E-08"
        izz="0.00263447481829551" />
    </inertial>
    <visual>
      <origin
        xyz="0 0 0"
        rpy="0 0 0" />
      <geometry>
        <mesh
          filename="package://car_3_wheel/meshes/car_right.STL" />
      </geometry>
      <material
        name="">
        <color
          rgba="1 0.549019607843137 0 1" />
      </material>
    </visual>
    <collision>
      <origin
        xyz="0 0 0"
        rpy="0 0 0" />
      <geometry>
        <mesh
          filename="package://car_3_wheel/meshes/car_right.STL" />
      </geometry>
    </collision>
  </link>
  <joint
    name="car_right_joint"
    type="continuous">
    <origin
      xyz="-0.094611 -0.21533 0.084967"
      rpy="-1.5708 0 0" />
    <parent
      link="base_link" />
    <child
      link="car_right" />
    <axis
      xyz="0 0 1" />
    <limit
      effort="10"
      velocity="10" />
    <dynamics
      damping="0.1"
      friction="0.1" />
  </joint>

 <gazebo reference="car_right">
    <mu1>200</mu1>
    <mu2>200</mu2>
    <kp>1000000</kp>
    <kd>1</kd>
    <material>Gazebo/Black</material>
  </gazebo>


  <link
    name="caster">
    <inertial>
      <origin
        xyz="-4.287577813053E-05 -3.94517439857456E-05 -0.0229494304113731"
        rpy="0 0 0" />
      <mass
        value="0.0206098306469479" />
      <inertia
        ixx="8.96575513496906E-06"
        ixy="6.503869015188E-07"
        ixz="-1.6807849402754E-08"
        iyy="9.20046463021548E-06"
        iyz="-2.0112053676607E-08"
        izz="8.194942339049E-06" />
    </inertial>
    <visual>
      <origin
        xyz="0 0 0"
        rpy="0 0 0" />
      <geometry>
        <mesh
          filename="package://car_3_wheel/meshes/caster.STL" />
      </geometry>
      <material
        name="">
        <color
          rgba="0.898039215686275 0.898039215686275 0.898039215686275 1" />
      </material>
    </visual>
    <collision>
      <origin
        xyz="0 0 0"
        rpy="0 0 0" />
      <geometry>
        <mesh
          filename="package://car_3_wheel/meshes/caster.STL" />
      </geometry>
    </collision>
  </link>
  <joint
    name="caster_joint"
    type="continuous">
    <origin
      xyz="0.093013 0.012666 0.0995"
      rpy="0 0 0" />
    <parent
      link="base_link" />
    <child
      link="caster" />
    <axis
      xyz="0 0 1" />
    <limit
      effort="10"
      velocity="10" />
    <dynamics
      damping="0.1"
      friction="0.1" />
  </joint>

  <link
    name="caster_wheel">
    <inertial>
      <origin
        xyz="6.44417181385193E-05 -3.98464710053698E-05 -0.000118799318220368"
        rpy="0 0 0" />
      <mass
        value="0.0846021989758955" />
      <inertia
        ixx="3.34341659764486E-05"
        ixy="4.83440269761966E-08"
        ixz="-6.37637246255802E-06"
        iyy="2.57103236366154E-05"
        iyz="-3.98693510412154E-08"
        izz="3.09738148971981E-05" />
    </inertial>
    <visual>
      <origin
        xyz="0 0 0"
        rpy="0 0 0" />
      <geometry>
        <mesh
          filename="package://car_3_wheel/meshes/caster_wheel.STL" />
      </geometry>
      <material
        name="">
        <color
          rgba="0.898039215686275 0.898039215686275 0.898039215686275 1" />
      </material>
    </visual>
    <collision>
      <origin
        xyz="0 0 0"
        rpy="0 0 0" />
      <geometry>
        <mesh
          filename="package://car_3_wheel/meshes/caster_wheel.STL" />
      </geometry>
    </collision>
  </link>
  <joint
    name="caster_wheel_joint"
    type="continuous">
    <origin
      xyz="0.00084256 -0.00097103 -0.069591"
      rpy="-1.5708 0 0" />
    <parent
      link="caster" />
    <child
      link="caster_wheel" />
    <axis
      xyz="0.76732 0 -0.64126" />
    <limit
      effort="10"
      velocity="10" />
    <dynamics
      damping="0.1"
      friction="0.1" />
  </joint>

  <gazebo reference="caster_wheel">
    <mu1>200</mu1>
    <mu2>200</mu2>
    <kp>1000000</kp>
    <kd>1</kd>
    <material>Gazebo/Black</material>
  </gazebo>

  <link
    name="lidar">
    <inertial>
      <origin
        xyz="-2.83946527987154E-05 6.77241922856196E-06 -0.0331869874350902"
        rpy="0 0 0" />
      <mass
        value="0.0597622086579142" />
      <inertia
        ixx="1.46799285574346E-05"
        ixy="-1.06540819018029E-09"
        ixz="-3.50094639085274E-09"
        iyy="1.67280502569906E-05"
        iyz="-2.22634366938571E-10"
        izz="1.97717799126785E-05" />
    </inertial>
    <visual>
      <origin
        xyz="0 0 0"
        rpy="0 0 0" />
      <geometry>
        <mesh
          filename="package://car_3_wheel/meshes/lidar.STL" />
      </geometry>
      <material
        name="">
        <color
          rgba="0.792156862745098 0.819607843137255 0.933333333333333 1" />
      </material>
    </visual>
    <collision>
      <origin
        xyz="0 0 0"
        rpy="0 0 0" />
      <geometry>
        <mesh
          filename="package://car_3_wheel/meshes/lidar.STL" />
      </geometry>
    </collision>
  </link>
  <joint
    name="lidar_joint"
    type="fixed">
    <origin
      xyz="-0.025099 0.0088282 0.23"
      rpy="0 0 0" />
    <parent
      link="base_link" />
    <child
      link="lidar" />
    <axis
      xyz="0 0 0" />
    <limit
      effort="10"
      velocity="10" />
    <dynamics
      damping="0.1"
      friction="0.1" />
  </joint>

  <gazebo reference="caster_wheel">
    <material>Gazebo/Black</material>
  </gazebo>


</robot>