<!-- <?xml version="1.0" encoding="utf-8"?> -->
<!-- This URDF was automatically created by SolidWorks to URDF Exporter! Originally created by Stephen Brawner (brawner@gmail.com) 
     Commit Version: 1.6.0-4-g7f85cfe  Build Version: 1.6.7995.38578
     For more information, please see http://wiki.ros.org/sw_urdf_exporter -->
<robot
  name="ver6">
  <link
    name="base_link">
    <inertial>
      <origin
        xyz="-0.0222751569698722 0.0118585384555541 0.116332514439535"
        rpy="0 0 0" />
      <mass
        value="0.12" />
      <inertia
        ixx="0.0001"
        ixy="0"
        ixz="0"
        iyy="0.0003"
        iyz="0"
        izz="0.0002" />
    </inertial>
    <visual>
      <origin
        xyz="0 0 0"
        rpy="0 0 0" />
      <geometry>
        <mesh
          filename="package://car_3_wheel/meshes/base_link.STL" />
      </geometry>
      <material
        name="">
        <color
          rgba="0.898039215686275 0.898039215686275 0.898039215686275 1" />
      </material>
    </visual>
    <collision>
      <origin
        xyz="0 0 0"
        rpy="0 0 0" />
      <geometry>
        <mesh
          filename="package://car_3_wheel/meshes/base_link.STL" />
      </geometry>
    </collision>
  </link>

  <gazebo reference="base_link">
    <mu1>200</mu1>
    <mu2>200</mu2>
    <kp>1000000</kp>
    <kd>1</kd>
    <material>Gazebo/Red</material>
  </gazebo>


  <link
    name="car_left">
    <inertial>
      <origin
        xyz="0.0002288419618732 -0.000132204138624934 -0.0180084261510948"
        rpy="0 0 0" />
      <mass
        value="0.1403" />
      <inertia
        ixx="0.00002"
        ixy="0"
        ixz="0"
        iyy="0.00002"
        iyz="0"
        izz="0.0001" />
    </inertial>
    <visual>
      <origin
        xyz="0 0 0"
        rpy="0 0 0" />
      <geometry>
        <mesh
          filename="package://car_3_wheel/meshes/car_left.STL" />
      </geometry>
      <material
        name="">
        <color
          rgba="1 0.549019607843137 0 1" />
      </material>
    </visual>
    <collision>
      <origin
        xyz="0 0 0"
        rpy="0 0 0" />
      <geometry>
        <mesh
          filename="package://car_3_wheel/meshes/car_left.STL" />
      </geometry>
    </collision>
  </link>
  <joint
    name="car_left_joint"
    type="continuous">
    <origin
      xyz="-0.095546 0.24067 0.084802"
      rpy="-1.5708 0 0" />
    <parent
      link="base_link" />
    <child
      link="car_left" />
    <axis
      xyz="0 0 1" />
    <limit
      effort="10"
      velocity="10" />
    <dynamics
      damping="0.1"
      friction="0.1" />
  </joint>

  <gazebo reference="car_left">
    <mu1>200</mu1>
    <mu2>200</mu2>
    <kp>1000000</kp>
    <kd>1</kd>
    <material>Gazebo/Black</material>
  </gazebo>

  <link
    name="car_right">
    <inertial>
      <origin
        xyz="-0.000260216250702383 -4.61723206129448E-05 0.0180084270297736"
        rpy="0 0 0" />
      <mass
        value="0.1403" />
      <inertia
        ixx="0.00002"
        ixy="0"
        ixz="0"
        iyy="0.00002"
        iyz="0"
        izz="0.0001" />
    </inertial>
    <visual>
      <origin
        xyz="0 0 0"
        rpy="0 0 0" />
      <geometry>
        <mesh
          filename="package://car_3_wheel/meshes/car_right.STL" />
      </geometry>
      <material
        name="">
        <color
          rgba="1 0.549019607843137 0 1" />
      </material>
    </visual>
    <collision>
      <origin
        xyz="0 0 0"
        rpy="0 0 0" />
      <geometry>
        <mesh
          filename="package://car_3_wheel/meshes/car_right.STL" />
      </geometry>
    </collision>
  </link>
  <joint
    name="car_right_joint"
    type="continuous">
    <origin
      xyz="-0.094611 -0.21533 0.084967"
      rpy="-1.5708 0 0" />
    <parent
      link="base_link" />
    <child
      link="car_right" />
    <axis
      xyz="0 0 1" />
    <limit
      effort="10"
      velocity="10" />
    <dynamics
      damping="0.1"
      friction="0.1" />
  </joint>

 <gazebo reference="car_right">
    <mu1>200</mu1>
    <mu2>200</mu2>
    <kp>1000000</kp>
    <kd>1</kd>
    <material>Gazebo/Black</material>
  </gazebo>


  <link
    name="caster">
    <inertial>
      <origin
        xyz="-4.287577813053E-05 -3.94517439857456E-05 -0.0229494304113731"
        rpy="0 0 0" />
      <mass
        value="0.5" />
      <inertia
        ixx="0.00004"
        ixy="0"
        ixz="0"
        iyy="0.00004"
        iyz="0"
        izz="0.00001"/>
    </inertial>
    <visual>
      <origin
        xyz="0 0 0"
        rpy="0 0 0" />
      <geometry>
        <mesh
          filename="package://car_3_wheel/meshes/caster.STL" />
      </geometry>
      <material
        name="">
        <color
          rgba="0.898039215686275 0.898039215686275 0.898039215686275 1" />
      </material>
    </visual>
    <collision>
      <origin
        xyz="0 0 0"
        rpy="0 0 0" />
      <geometry>
        <mesh
          filename="package://car_3_wheel/meshes/caster.STL" />
      </geometry>
    </collision>
  </link>

  <gazebo reference="caster">
    <mu1>0.1</mu1>
    <mu2>0.1</mu2>
    <kp>1000000</kp>
    <kd>1</kd>
    <material>Gazebo/Gray</material>
  </gazebo>

  <joint
    name="caster_joint"
    type="continuous">
    <origin
      xyz="0.093013 0.012666 0.0995"
      rpy="0 0 0" />
    <parent
      link="base_link" />
    <child
      link="caster" />
    <axis
      xyz="0 0 1" />
    <limit
      effort="10"
      velocity="10" />
    <dynamics
      damping="0.1"
      friction="0.1" />
  </joint>

  <link
    name="caster_wheel">
    <inertial>
      <origin
        xyz="6.44417181385193E-05 -3.98464710053698E-05 -0.000118799318220368"
        rpy="0 0 0" />
      <mass
        value="0.0846021989758955" />
      <inertia
        ixx="0.0004"
        ixy="0"
        ixz="0"
        iyy="0.0004"
        iyz="0"
        izz="0.00001" />
    </inertial>
    <visual>
      <origin
        xyz="0 0 0"
        rpy="0 0 0" />
      <geometry>
        <mesh
          filename="package://car_3_wheel/meshes/caster_wheel.STL" />
      </geometry>
      <material
        name="">
        <color
          rgba="0.898039215686275 0.898039215686275 0.898039215686275 1" />
      </material>
    </visual>
    <collision>
      <origin
        xyz="0 0 0"
        rpy="0 0 0" />
      <geometry>
        <mesh
          filename="package://car_3_wheel/meshes/caster_wheel.STL" />
      </geometry>
    </collision>
  </link>

  <gazebo reference="caster_wheel">
    <mu1>0.1</mu1>
    <mu2>0.1</mu2>
    <kp>1000000</kp>
    <kd>1</kd>
    <material>Gazebo/Black</material>
  </gazebo>

  <joint
    name="caster_wheel_joint"
    type="continuous">
    <origin
      xyz="0.00084256 -0.00097103 -0.069591"
      rpy="-1.5708 0 0" />
    <parent
      link="caster" />
    <child
      link="caster_wheel" />
    <axis
      xyz="0.76732 0 -0.64126" />
    <limit
      effort="10"
      velocity="10" />
    <dynamics
      damping="0.1"
      friction="0.1" />
  </joint>

  <link
    name="lidar">
    <inertial>
      <origin
        xyz="-2.83946527987154E-05 6.77241922856196E-06 -0.0331869874350902"
        rpy="0 0 0" />
      <mass
        value="0.0597622086579142" />
      <inertia
        ixx="1.46799285574346E-05"
        ixy="-1.06540819018029E-09"
        ixz="-3.50094639085274E-09"
        iyy="1.67280502569906E-05"
        iyz="-2.22634366938571E-10"
        izz="1.97717799126785E-05" />
    </inertial>
    <visual>
      <origin
        xyz="0 0 0"
        rpy="0 0 0" />
      <geometry>
        <mesh
          filename="package://car_3_wheel/meshes/lidar.STL" />
      </geometry>
      <material
        name="">
        <color
          rgba="0.792156862745098 0.819607843137255 0.933333333333333 1" />
      </material>
    </visual>
    <collision>
      <origin
        xyz="0 0 0"
        rpy="0 0 0" />
      <geometry>
        <mesh
          filename="package://car_3_wheel/meshes/lidar.STL" />
      </geometry>
    </collision>
  </link>
  <joint
    name="lidar_joint"
    type="fixed">
    <origin
      xyz="-0.025099 0.0088282 0.23"
      rpy="0 0 0" />
    <parent
      link="base_link" />
    <child
      link="lidar" />
    <axis
      xyz="0 0 0" />
    <limit
      effort="10"
      velocity="10" />
    <dynamics
      damping="0.1"
      friction="0.1" />
  </joint>

<!-- Plugin cho Lidar -->
  <gazebo reference="lidar">
    <sensor name="lidar" type="ray">
      <always_on>true</always_on>
      <visualize>true</visualize>
      <update_rate>10</update_rate> 
      <ray>
        <scan>
          <horizontal>
            <samples>10</samples> 
            <resolution>1.0</resolution>
            <min_angle>-1.57</min_angle>
            <max_angle>1.57</max_angle>
          </horizontal>
        </scan>
        <range>
          <min>0.3</min>
          <max>15.0</max> 
          <resolution>0.015</resolution>
        </range>
        <noise>
          <type>gaussian</type>
          <mean>0.0</mean>
          <stddev>0.01</stddev>
        </noise>
      </ray>
      <plugin name="scan" filename="libgazebo_ros_ray_sensor.so">
        <ros>
          <remapping>~/out:=scan</remapping>
        </ros>
        <output_type>sensor_msgs/LaserScan</output_type>
        <frame_name>lidar</frame_name>
      </plugin>
    </sensor>
    <mu1>0.01</mu1>
    <mu2>0.01</mu2>
    <material>Gazebo/Black</material>
  </gazebo>

  <gazebo reference="lidar">
    <material>Gazebo/Black</material>
  </gazebo>

  <gazebo>
    <plugin name="two_wheeled_robot_diff_drive" filename="libgazebo_ros_diff_drive.so">
 
      <update_rate>30</update_rate>
      
      <!-- wheels -->
      <left_joint>car_left_joint</left_joint>
      <right_joint>car_right_joint</right_joint>
 
      <!-- kinematics -->
      <wheel_separation>0.16</wheel_separation>
      <wheel_diameter>0.4</wheel_diameter>
 
      <!-- limits -->
      <max_wheel_torque>20</max_wheel_torque>
      <max_wheel_acceleration>20.0</max_wheel_acceleration>
 
      <!-- Receive velocity commands on this ROS topic -->
      <command_topic>cmd_vel</command_topic>
 
      <!-- output -->
      <!-- When false, publish no wheel odometry data to a ROS topic -->
      <publish_odom>true</publish_odom>
 
      <!-- When true, publish coordinate transform from odom to base_footprint -->
      <!-- I usually use the robot_localization package to publish this transform -->  
      <publish_odom_tf>true</publish_odom_tf>
     
      <!-- When true, publish coordinate transform from base_link to the wheels -->
      <!-- The robot_state_publisher package is often used to publish this transform -->  
      <publish_wheel_tf>true</publish_wheel_tf>
 
      <odometry_topic>odom</odometry_topic>
      <odometry_frame>odom</odometry_frame>
      <robot_base_frame>base_link</robot_base_frame>
 
      <odometry_source>1</odometry_source>
      <ros>
        <remapping>odom:=wheel/odometry</remapping>
      </ros>
    </plugin>
  </gazebo>

  <gazebo>
    <plugin name="gazebo_ros_joint_state_publisher"
        filename="libgazebo_ros_joint_state_publisher.so">
        <update_rate>100</update_rate>
        <joint_name>caster_joint</joint_name>
        <joint_name>caster_wheel_joint</joint_name>
    </plugin>
  </gazebo>

</robot>
